[2025-07-01 03:40:45 +0000] [89] [INFO] Starting gunicorn 23.0.0
[2025-07-01 03:40:45 +0000] [89] [INFO] Listening at: unix:/app/aws_gpu_monitoring/gunicorn.sock (89)
[2025-07-01 03:40:45 +0000] [89] [INFO] Using worker: sync
[2025-07-01 03:40:45 +0000] [95] [INFO] Booting worker with pid: 95
[2025-07-01 03:40:45 +0000] [95] [ERROR] Exception in worker process
Traceback (most recent call last):
  File "/app/venv_awsgpu/lib/python3.10/site-packages/gunicorn/arbiter.py", line 608, in spawn_worker
    worker.init_process()
  File "/app/venv_awsgpu/lib/python3.10/site-packages/gunicorn/workers/base.py", line 135, in init_process
    self.load_wsgi()
  File "/app/venv_awsgpu/lib/python3.10/site-packages/gunicorn/workers/base.py", line 147, in load_wsgi
    self.wsgi = self.app.wsgi()
  File "/app/venv_awsgpu/lib/python3.10/site-packages/gunicorn/app/base.py", line 66, in wsgi
    self.callable = self.load()
  File "/app/venv_awsgpu/lib/python3.10/site-packages/gunicorn/app/wsgiapp.py", line 57, in load
    return self.load_wsgiapp()
  File "/app/venv_awsgpu/lib/python3.10/site-packages/gunicorn/app/wsgiapp.py", line 47, in load_wsgiapp
    return util.import_app(self.app_uri)
  File "/app/venv_awsgpu/lib/python3.10/site-packages/gunicorn/util.py", line 370, in import_app
    mod = importlib.import_module(module)
  File "/usr/lib/python3.10/importlib/__init__.py", line 126, in import_module
    return _bootstrap._gcd_import(name[level:], package, level)
  File "<frozen importlib._bootstrap>", line 1050, in _gcd_import
  File "<frozen importlib._bootstrap>", line 1027, in _find_and_load
  File "<frozen importlib._bootstrap>", line 992, in _find_and_load_unlocked
  File "<frozen importlib._bootstrap>", line 241, in _call_with_frames_removed
  File "<frozen importlib._bootstrap>", line 1050, in _gcd_import
  File "<frozen importlib._bootstrap>", line 1027, in _find_and_load
  File "<frozen importlib._bootstrap>", line 1004, in _find_and_load_unlocked
ModuleNotFoundError: No module named 'aws_gpu_monitoring.aws_gpu_monitoring'
[2025-07-01 03:40:45 +0000] [95] [INFO] Worker exiting (pid: 95)
[2025-07-01 03:40:45 +0000] [89] [ERROR] Worker (pid:95) exited with code 3
[2025-07-01 03:40:45 +0000] [89] [ERROR] Shutting down: Master
[2025-07-01 03:40:45 +0000] [89] [ERROR] Reason: Worker failed to boot.
[2025-07-01 03:41:25 +0000] [102] [INFO] Starting gunicorn 23.0.0
[2025-07-01 03:41:25 +0000] [102] [INFO] Listening at: unix:/app/aws_gpu_monitoring/gunicorn.sock (102)
[2025-07-01 03:41:25 +0000] [102] [INFO] Using worker: sync
[2025-07-01 03:41:25 +0000] [107] [INFO] Booting worker with pid: 107
[2025-07-01 03:41:25 +0000] [108] [INFO] Booting worker with pid: 108
[2025-07-01 03:41:25 +0000] [109] [INFO] Booting worker with pid: 109
[2025-07-01 03:59:30 +0000] [107] [INFO] Worker exiting (pid: 107)
[2025-07-01 03:59:30 +0000] [108] [INFO] Worker exiting (pid: 108)
[2025-07-01 03:59:30 +0000] [109] [INFO] Worker exiting (pid: 109)
[2025-07-01 03:59:30 +0000] [102] [INFO] Handling signal: term
[2025-07-01 03:59:31 +0000] [102] [INFO] Shutting down: Master
[2025-07-01 03:59:31 +0000] [116] [INFO] Starting gunicorn 23.0.0
[2025-07-01 03:59:31 +0000] [116] [INFO] Listening at: unix:/app/aws_gpu_monitoring/gunicorn.sock (116)
[2025-07-01 03:59:31 +0000] [116] [INFO] Using worker: sync
[2025-07-01 03:59:31 +0000] [122] [INFO] Booting worker with pid: 122
[2025-07-01 03:59:31 +0000] [123] [INFO] Booting worker with pid: 123
[2025-07-01 03:59:31 +0000] [124] [INFO] Booting worker with pid: 124
[2025-07-01 04:04:51 +0000] [124] [INFO] Worker exiting (pid: 124)
[2025-07-01 04:04:51 +0000] [123] [INFO] Worker exiting (pid: 123)
[2025-07-01 04:04:51 +0000] [122] [INFO] Worker exiting (pid: 122)
[2025-07-01 04:04:51 +0000] [116] [INFO] Handling signal: term
[2025-07-01 04:04:51 +0000] [116] [INFO] Shutting down: Master
[2025-07-01 04:04:51 +0000] [131] [INFO] Starting gunicorn 23.0.0
[2025-07-01 04:04:51 +0000] [131] [INFO] Listening at: unix:/app/aws_gpu_monitoring/gunicorn.sock (131)
[2025-07-01 04:04:51 +0000] [131] [INFO] Using worker: sync
[2025-07-01 04:04:51 +0000] [137] [INFO] Booting worker with pid: 137
[2025-07-01 04:04:51 +0000] [138] [INFO] Booting worker with pid: 138
[2025-07-01 04:04:52 +0000] [139] [INFO] Booting worker with pid: 139
[2025-07-01 04:05:02 +0000] [138] [ERROR] Error handling request /
Traceback (most recent call last):
  File "/app/venv_awsgpu/lib/python3.10/site-packages/django/core/handlers/exception.py", line 55, in inner
    response = get_response(request)
  File "/app/venv_awsgpu/lib/python3.10/site-packages/django/core/handlers/base.py", line 181, in _get_response
    callback, callback_args, callback_kwargs = self.resolve_request(request)
  File "/app/venv_awsgpu/lib/python3.10/site-packages/django/core/handlers/base.py", line 313, in resolve_request
    resolver_match = resolver.resolve(request.path_info)
  File "/app/venv_awsgpu/lib/python3.10/site-packages/django/urls/resolvers.py", line 666, in resolve
    for pattern in self.url_patterns:
  File "/app/venv_awsgpu/lib/python3.10/site-packages/django/utils/functional.py", line 47, in __get__
    res = instance.__dict__[self.name] = self.func(instance)
  File "/app/venv_awsgpu/lib/python3.10/site-packages/django/urls/resolvers.py", line 718, in url_patterns
    patterns = getattr(self.urlconf_module, "urlpatterns", self.urlconf_module)
  File "/app/venv_awsgpu/lib/python3.10/site-packages/django/utils/functional.py", line 47, in __get__
    res = instance.__dict__[self.name] = self.func(instance)
  File "/app/venv_awsgpu/lib/python3.10/site-packages/django/urls/resolvers.py", line 711, in urlconf_module
    return import_module(self.urlconf_name)
  File "/usr/lib/python3.10/importlib/__init__.py", line 126, in import_module
    return _bootstrap._gcd_import(name[level:], package, level)
  File "<frozen importlib._bootstrap>", line 1050, in _gcd_import
  File "<frozen importlib._bootstrap>", line 1027, in _find_and_load
  File "<frozen importlib._bootstrap>", line 1006, in _find_and_load_unlocked
  File "<frozen importlib._bootstrap>", line 688, in _load_unlocked
  File "<frozen importlib._bootstrap_external>", line 883, in exec_module
  File "<frozen importlib._bootstrap>", line 241, in _call_with_frames_removed
  File "/app/aws_gpu_monitoring/aws_gpu_monitoring/urls.py", line 22, in <module>
    path('', include('server_manager.urls')),  # server_manager 앱의 URL 포함
  File "/app/venv_awsgpu/lib/python3.10/site-packages/django/urls/conf.py", line 39, in include
    urlconf_module = import_module(urlconf_module)
  File "/usr/lib/python3.10/importlib/__init__.py", line 126, in import_module
    return _bootstrap._gcd_import(name[level:], package, level)
  File "<frozen importlib._bootstrap>", line 1050, in _gcd_import
  File "<frozen importlib._bootstrap>", line 1027, in _find_and_load
  File "<frozen importlib._bootstrap>", line 1006, in _find_and_load_unlocked
  File "<frozen importlib._bootstrap>", line 688, in _load_unlocked
  File "<frozen importlib._bootstrap_external>", line 883, in exec_module
  File "<frozen importlib._bootstrap>", line 241, in _call_with_frames_removed
  File "/app/aws_gpu_monitoring/server_manager/urls.py", line 2, in <module>
    from . import views
  File "/app/aws_gpu_monitoring/server_manager/views.py", line 8, in <module>
    from .ec2_service import EC2Service
  File "/app/aws_gpu_monitoring/server_manager/ec2_service.py", line 7, in <module>
    from server_manager.models.instance import Instance
  File "/app/aws_gpu_monitoring/server_manager/models/__init__.py", line 1, in <module>
    from .instance import Instance
  File "/app/aws_gpu_monitoring/server_manager/models/instance.py", line 3, in <module>
    class Instance(models.Model):
  File "/app/venv_awsgpu/lib/python3.10/site-packages/django/db/models/base.py", line 136, in __new__
    raise RuntimeError(
RuntimeError: Model class server_manager.models.instance.Instance doesn't declare an explicit app_label and isn't in an application in INSTALLED_APPS.

During handling of the above exception, another exception occurred:

Traceback (most recent call last):
  File "/app/venv_awsgpu/lib/python3.10/site-packages/django/core/handlers/exception.py", line 55, in inner
    response = get_response(request)
  File "/app/venv_awsgpu/lib/python3.10/site-packages/django/utils/deprecation.py", line 120, in __call__
    response = response or self.get_response(request)
  File "/app/venv_awsgpu/lib/python3.10/site-packages/django/core/handlers/exception.py", line 57, in inner
    response = response_for_exception(request, exc)
  File "/app/venv_awsgpu/lib/python3.10/site-packages/django/core/handlers/exception.py", line 141, in response_for_exception
    response = handle_uncaught_exception(
  File "/app/venv_awsgpu/lib/python3.10/site-packages/django/core/handlers/exception.py", line 182, in handle_uncaught_exception
    return debug.technical_500_response(request, *exc_info)
  File "/app/venv_awsgpu/lib/python3.10/site-packages/django/views/debug.py", line 69, in technical_500_response
    html = reporter.get_traceback_html()
  File "/app/venv_awsgpu/lib/python3.10/site-packages/django/views/debug.py", line 428, in get_traceback_html
    c = Context(self.get_traceback_data(), use_l10n=False)
  File "/app/venv_awsgpu/lib/python3.10/site-packages/django/views/debug.py", line 411, in get_traceback_data
    c["raising_view_name"] = get_caller(self.request)
  File "/app/venv_awsgpu/lib/python3.10/site-packages/django/views/debug.py", line 102, in get_caller
    resolver_match = resolve(request.path)
  File "/app/venv_awsgpu/lib/python3.10/site-packages/django/urls/base.py", line 25, in resolve
    return get_resolver(urlconf).resolve(path)
  File "/app/venv_awsgpu/lib/python3.10/site-packages/django/urls/resolvers.py", line 666, in resolve
    for pattern in self.url_patterns:
  File "/app/venv_awsgpu/lib/python3.10/site-packages/django/utils/functional.py", line 47, in __get__
    res = instance.__dict__[self.name] = self.func(instance)
  File "/app/venv_awsgpu/lib/python3.10/site-packages/django/urls/resolvers.py", line 718, in url_patterns
    patterns = getattr(self.urlconf_module, "urlpatterns", self.urlconf_module)
  File "/app/venv_awsgpu/lib/python3.10/site-packages/django/utils/functional.py", line 47, in __get__
    res = instance.__dict__[self.name] = self.func(instance)
  File "/app/venv_awsgpu/lib/python3.10/site-packages/django/urls/resolvers.py", line 711, in urlconf_module
    return import_module(self.urlconf_name)
  File "/usr/lib/python3.10/importlib/__init__.py", line 126, in import_module
    return _bootstrap._gcd_import(name[level:], package, level)
  File "<frozen importlib._bootstrap>", line 1050, in _gcd_import
  File "<frozen importlib._bootstrap>", line 1027, in _find_and_load
  File "<frozen importlib._bootstrap>", line 1006, in _find_and_load_unlocked
  File "<frozen importlib._bootstrap>", line 688, in _load_unlocked
  File "<frozen importlib._bootstrap_external>", line 883, in exec_module
  File "<frozen importlib._bootstrap>", line 241, in _call_with_frames_removed
  File "/app/aws_gpu_monitoring/aws_gpu_monitoring/urls.py", line 22, in <module>
    path('', include('server_manager.urls')),  # server_manager 앱의 URL 포함
  File "/app/venv_awsgpu/lib/python3.10/site-packages/django/urls/conf.py", line 39, in include
    urlconf_module = import_module(urlconf_module)
  File "/usr/lib/python3.10/importlib/__init__.py", line 126, in import_module
    return _bootstrap._gcd_import(name[level:], package, level)
  File "<frozen importlib._bootstrap>", line 1050, in _gcd_import
  File "<frozen importlib._bootstrap>", line 1027, in _find_and_load
  File "<frozen importlib._bootstrap>", line 1006, in _find_and_load_unlocked
  File "<frozen importlib._bootstrap>", line 688, in _load_unlocked
  File "<frozen importlib._bootstrap_external>", line 883, in exec_module
  File "<frozen importlib._bootstrap>", line 241, in _call_with_frames_removed
  File "/app/aws_gpu_monitoring/server_manager/urls.py", line 2, in <module>
    from . import views
  File "/app/aws_gpu_monitoring/server_manager/views.py", line 8, in <module>
    from .ec2_service import EC2Service
  File "/app/aws_gpu_monitoring/server_manager/ec2_service.py", line 7, in <module>
    from server_manager.models.instance import Instance
  File "/app/aws_gpu_monitoring/server_manager/models/__init__.py", line 1, in <module>
    from .instance import Instance
  File "/app/aws_gpu_monitoring/server_manager/models/instance.py", line 3, in <module>
    class Instance(models.Model):
  File "/app/venv_awsgpu/lib/python3.10/site-packages/django/db/models/base.py", line 136, in __new__
    raise RuntimeError(
RuntimeError: Model class server_manager.models.instance.Instance doesn't declare an explicit app_label and isn't in an application in INSTALLED_APPS.

During handling of the above exception, another exception occurred:

Traceback (most recent call last):
  File "/app/venv_awsgpu/lib/python3.10/site-packages/django/core/handlers/exception.py", line 55, in inner
    response = get_response(request)
  File "/app/venv_awsgpu/lib/python3.10/site-packages/django/utils/deprecation.py", line 120, in __call__
    response = response or self.get_response(request)
  File "/app/venv_awsgpu/lib/python3.10/site-packages/django/core/handlers/exception.py", line 57, in inner
    response = response_for_exception(request, exc)
  File "/app/venv_awsgpu/lib/python3.10/site-packages/django/core/handlers/exception.py", line 141, in response_for_exception
    response = handle_uncaught_exception(
  File "/app/venv_awsgpu/lib/python3.10/site-packages/django/core/handlers/exception.py", line 182, in handle_uncaught_exception
    return debug.technical_500_response(request, *exc_info)
  File "/app/venv_awsgpu/lib/python3.10/site-packages/django/views/debug.py", line 69, in technical_500_response
    html = reporter.get_traceback_html()
  File "/app/venv_awsgpu/lib/python3.10/site-packages/django/views/debug.py", line 428, in get_traceback_html
    c = Context(self.get_traceback_data(), use_l10n=False)
  File "/app/venv_awsgpu/lib/python3.10/site-packages/django/views/debug.py", line 411, in get_traceback_data
    c["raising_view_name"] = get_caller(self.request)
  File "/app/venv_awsgpu/lib/python3.10/site-packages/django/views/debug.py", line 102, in get_caller
    resolver_match = resolve(request.path)
  File "/app/venv_awsgpu/lib/python3.10/site-packages/django/urls/base.py", line 25, in resolve
    return get_resolver(urlconf).resolve(path)
  File "/app/venv_awsgpu/lib/python3.10/site-packages/django/urls/resolvers.py", line 666, in resolve
    for pattern in self.url_patterns:
  File "/app/venv_awsgpu/lib/python3.10/site-packages/django/utils/functional.py", line 47, in __get__
    res = instance.__dict__[self.name] = self.func(instance)
  File "/app/venv_awsgpu/lib/python3.10/site-packages/django/urls/resolvers.py", line 718, in url_patterns
    patterns = getattr(self.urlconf_module, "urlpatterns", self.urlconf_module)
  File "/app/venv_awsgpu/lib/python3.10/site-packages/django/utils/functional.py", line 47, in __get__
    res = instance.__dict__[self.name] = self.func(instance)
  File "/app/venv_awsgpu/lib/python3.10/site-packages/django/urls/resolvers.py", line 711, in urlconf_module
    return import_module(self.urlconf_name)
  File "/usr/lib/python3.10/importlib/__init__.py", line 126, in import_module
    return _bootstrap._gcd_import(name[level:], package, level)
  File "<frozen importlib._bootstrap>", line 1050, in _gcd_import
  File "<frozen importlib._bootstrap>", line 1027, in _find_and_load
  File "<frozen importlib._bootstrap>", line 1006, in _find_and_load_unlocked
  File "<frozen importlib._bootstrap>", line 688, in _load_unlocked
  File "<frozen importlib._bootstrap_external>", line 883, in exec_module
  File "<frozen importlib._bootstrap>", line 241, in _call_with_frames_removed
  File "/app/aws_gpu_monitoring/aws_gpu_monitoring/urls.py", line 22, in <module>
    path('', include('server_manager.urls')),  # server_manager 앱의 URL 포함
  File "/app/venv_awsgpu/lib/python3.10/site-packages/django/urls/conf.py", line 39, in include
    urlconf_module = import_module(urlconf_module)
  File "/usr/lib/python3.10/importlib/__init__.py", line 126, in import_module
    return _bootstrap._gcd_import(name[level:], package, level)
  File "<frozen importlib._bootstrap>", line 1050, in _gcd_import
  File "<frozen importlib._bootstrap>", line 1027, in _find_and_load
  File "<frozen importlib._bootstrap>", line 1006, in _find_and_load_unlocked
  File "<frozen importlib._bootstrap>", line 688, in _load_unlocked
  File "<frozen importlib._bootstrap_external>", line 883, in exec_module
  File "<frozen importlib._bootstrap>", line 241, in _call_with_frames_removed
  File "/app/aws_gpu_monitoring/server_manager/urls.py", line 2, in <module>
    from . import views
  File "/app/aws_gpu_monitoring/server_manager/views.py", line 8, in <module>
    from .ec2_service import EC2Service
  File "/app/aws_gpu_monitoring/server_manager/ec2_service.py", line 7, in <module>
    from server_manager.models.instance import Instance
  File "/app/aws_gpu_monitoring/server_manager/models/__init__.py", line 1, in <module>
    from .instance import Instance
  File "/app/aws_gpu_monitoring/server_manager/models/instance.py", line 3, in <module>
    class Instance(models.Model):
  File "/app/venv_awsgpu/lib/python3.10/site-packages/django/db/models/base.py", line 136, in __new__
    raise RuntimeError(
RuntimeError: Model class server_manager.models.instance.Instance doesn't declare an explicit app_label and isn't in an application in INSTALLED_APPS.

During handling of the above exception, another exception occurred:

Traceback (most recent call last):
  File "/app/venv_awsgpu/lib/python3.10/site-packages/django/core/handlers/exception.py", line 55, in inner
    response = get_response(request)
  File "/app/venv_awsgpu/lib/python3.10/site-packages/django/utils/deprecation.py", line 120, in __call__
    response = response or self.get_response(request)
  File "/app/venv_awsgpu/lib/python3.10/site-packages/django/core/handlers/exception.py", line 57, in inner
    response = response_for_exception(request, exc)
  File "/app/venv_awsgpu/lib/python3.10/site-packages/django/core/handlers/exception.py", line 141, in response_for_exception
    response = handle_uncaught_exception(
  File "/app/venv_awsgpu/lib/python3.10/site-packages/django/core/handlers/exception.py", line 182, in handle_uncaught_exception
    return debug.technical_500_response(request, *exc_info)
  File "/app/venv_awsgpu/lib/python3.10/site-packages/django/views/debug.py", line 69, in technical_500_response
    html = reporter.get_traceback_html()
  File "/app/venv_awsgpu/lib/python3.10/site-packages/django/views/debug.py", line 428, in get_traceback_html
    c = Context(self.get_traceback_data(), use_l10n=False)
  File "/app/venv_awsgpu/lib/python3.10/site-packages/django/views/debug.py", line 411, in get_traceback_data
    c["raising_view_name"] = get_caller(self.request)
  File "/app/venv_awsgpu/lib/python3.10/site-packages/django/views/debug.py", line 102, in get_caller
    resolver_match = resolve(request.path)
  File "/app/venv_awsgpu/lib/python3.10/site-packages/django/urls/base.py", line 25, in resolve
    return get_resolver(urlconf).resolve(path)
  File "/app/venv_awsgpu/lib/python3.10/site-packages/django/urls/resolvers.py", line 666, in resolve
    for pattern in self.url_patterns:
  File "/app/venv_awsgpu/lib/python3.10/site-packages/django/utils/functional.py", line 47, in __get__
    res = instance.__dict__[self.name] = self.func(instance)
  File "/app/venv_awsgpu/lib/python3.10/site-packages/django/urls/resolvers.py", line 718, in url_patterns
    patterns = getattr(self.urlconf_module, "urlpatterns", self.urlconf_module)
  File "/app/venv_awsgpu/lib/python3.10/site-packages/django/utils/functional.py", line 47, in __get__
    res = instance.__dict__[self.name] = self.func(instance)
  File "/app/venv_awsgpu/lib/python3.10/site-packages/django/urls/resolvers.py", line 711, in urlconf_module
    return import_module(self.urlconf_name)
  File "/usr/lib/python3.10/importlib/__init__.py", line 126, in import_module
    return _bootstrap._gcd_import(name[level:], package, level)
  File "<frozen importlib._bootstrap>", line 1050, in _gcd_import
  File "<frozen importlib._bootstrap>", line 1027, in _find_and_load
  File "<frozen importlib._bootstrap>", line 1006, in _find_and_load_unlocked
  File "<frozen importlib._bootstrap>", line 688, in _load_unlocked
  File "<frozen importlib._bootstrap_external>", line 883, in exec_module
  File "<frozen importlib._bootstrap>", line 241, in _call_with_frames_removed
  File "/app/aws_gpu_monitoring/aws_gpu_monitoring/urls.py", line 22, in <module>
    path('', include('server_manager.urls')),  # server_manager 앱의 URL 포함
  File "/app/venv_awsgpu/lib/python3.10/site-packages/django/urls/conf.py", line 39, in include
    urlconf_module = import_module(urlconf_module)
  File "/usr/lib/python3.10/importlib/__init__.py", line 126, in import_module
    return _bootstrap._gcd_import(name[level:], package, level)
  File "<frozen importlib._bootstrap>", line 1050, in _gcd_import
  File "<frozen importlib._bootstrap>", line 1027, in _find_and_load
  File "<frozen importlib._bootstrap>", line 1006, in _find_and_load_unlocked
  File "<frozen importlib._bootstrap>", line 688, in _load_unlocked
  File "<frozen importlib._bootstrap_external>", line 883, in exec_module
  File "<frozen importlib._bootstrap>", line 241, in _call_with_frames_removed
  File "/app/aws_gpu_monitoring/server_manager/urls.py", line 2, in <module>
    from . import views
  File "/app/aws_gpu_monitoring/server_manager/views.py", line 8, in <module>
    from .ec2_service import EC2Service
  File "/app/aws_gpu_monitoring/server_manager/ec2_service.py", line 7, in <module>
    from server_manager.models.instance import Instance
  File "/app/aws_gpu_monitoring/server_manager/models/__init__.py", line 1, in <module>
    from .instance import Instance
  File "/app/aws_gpu_monitoring/server_manager/models/instance.py", line 3, in <module>
    class Instance(models.Model):
  File "/app/venv_awsgpu/lib/python3.10/site-packages/django/db/models/base.py", line 136, in __new__
    raise RuntimeError(
RuntimeError: Model class server_manager.models.instance.Instance doesn't declare an explicit app_label and isn't in an application in INSTALLED_APPS.

During handling of the above exception, another exception occurred:

Traceback (most recent call last):
  File "/app/venv_awsgpu/lib/python3.10/site-packages/django/core/handlers/exception.py", line 55, in inner
    response = get_response(request)
  File "/app/venv_awsgpu/lib/python3.10/site-packages/django/utils/deprecation.py", line 120, in __call__
    response = response or self.get_response(request)
  File "/app/venv_awsgpu/lib/python3.10/site-packages/django/core/handlers/exception.py", line 57, in inner
    response = response_for_exception(request, exc)
  File "/app/venv_awsgpu/lib/python3.10/site-packages/django/core/handlers/exception.py", line 141, in response_for_exception
    response = handle_uncaught_exception(
  File "/app/venv_awsgpu/lib/python3.10/site-packages/django/core/handlers/exception.py", line 182, in handle_uncaught_exception
    return debug.technical_500_response(request, *exc_info)
  File "/app/venv_awsgpu/lib/python3.10/site-packages/django/views/debug.py", line 69, in technical_500_response
    html = reporter.get_traceback_html()
  File "/app/venv_awsgpu/lib/python3.10/site-packages/django/views/debug.py", line 428, in get_traceback_html
    c = Context(self.get_traceback_data(), use_l10n=False)
  File "/app/venv_awsgpu/lib/python3.10/site-packages/django/views/debug.py", line 411, in get_traceback_data
    c["raising_view_name"] = get_caller(self.request)
  File "/app/venv_awsgpu/lib/python3.10/site-packages/django/views/debug.py", line 102, in get_caller
    resolver_match = resolve(request.path)
  File "/app/venv_awsgpu/lib/python3.10/site-packages/django/urls/base.py", line 25, in resolve
    return get_resolver(urlconf).resolve(path)
  File "/app/venv_awsgpu/lib/python3.10/site-packages/django/urls/resolvers.py", line 666, in resolve
    for pattern in self.url_patterns:
  File "/app/venv_awsgpu/lib/python3.10/site-packages/django/utils/functional.py", line 47, in __get__
    res = instance.__dict__[self.name] = self.func(instance)
  File "/app/venv_awsgpu/lib/python3.10/site-packages/django/urls/resolvers.py", line 718, in url_patterns
    patterns = getattr(self.urlconf_module, "urlpatterns", self.urlconf_module)
  File "/app/venv_awsgpu/lib/python3.10/site-packages/django/utils/functional.py", line 47, in __get__
    res = instance.__dict__[self.name] = self.func(instance)
  File "/app/venv_awsgpu/lib/python3.10/site-packages/django/urls/resolvers.py", line 711, in urlconf_module
    return import_module(self.urlconf_name)
  File "/usr/lib/python3.10/importlib/__init__.py", line 126, in import_module
    return _bootstrap._gcd_import(name[level:], package, level)
  File "<frozen importlib._bootstrap>", line 1050, in _gcd_import
  File "<frozen importlib._bootstrap>", line 1027, in _find_and_load
  File "<frozen importlib._bootstrap>", line 1006, in _find_and_load_unlocked
  File "<frozen importlib._bootstrap>", line 688, in _load_unlocked
  File "<frozen importlib._bootstrap_external>", line 883, in exec_module
  File "<frozen importlib._bootstrap>", line 241, in _call_with_frames_removed
  File "/app/aws_gpu_monitoring/aws_gpu_monitoring/urls.py", line 22, in <module>
    path('', include('server_manager.urls')),  # server_manager 앱의 URL 포함
  File "/app/venv_awsgpu/lib/python3.10/site-packages/django/urls/conf.py", line 39, in include
    urlconf_module = import_module(urlconf_module)
  File "/usr/lib/python3.10/importlib/__init__.py", line 126, in import_module
    return _bootstrap._gcd_import(name[level:], package, level)
  File "<frozen importlib._bootstrap>", line 1050, in _gcd_import
  File "<frozen importlib._bootstrap>", line 1027, in _find_and_load
  File "<frozen importlib._bootstrap>", line 1006, in _find_and_load_unlocked
  File "<frozen importlib._bootstrap>", line 688, in _load_unlocked
  File "<frozen importlib._bootstrap_external>", line 883, in exec_module
  File "<frozen importlib._bootstrap>", line 241, in _call_with_frames_removed
  File "/app/aws_gpu_monitoring/server_manager/urls.py", line 2, in <module>
    from . import views
  File "/app/aws_gpu_monitoring/server_manager/views.py", line 8, in <module>
    from .ec2_service import EC2Service
  File "/app/aws_gpu_monitoring/server_manager/ec2_service.py", line 7, in <module>
    from server_manager.models.instance import Instance
  File "/app/aws_gpu_monitoring/server_manager/models/__init__.py", line 1, in <module>
    from .instance import Instance
  File "/app/aws_gpu_monitoring/server_manager/models/instance.py", line 3, in <module>
    class Instance(models.Model):
  File "/app/venv_awsgpu/lib/python3.10/site-packages/django/db/models/base.py", line 136, in __new__
    raise RuntimeError(
RuntimeError: Model class server_manager.models.instance.Instance doesn't declare an explicit app_label and isn't in an application in INSTALLED_APPS.

During handling of the above exception, another exception occurred:

Traceback (most recent call last):
  File "/app/venv_awsgpu/lib/python3.10/site-packages/django/core/handlers/exception.py", line 55, in inner
    response = get_response(request)
  File "/app/venv_awsgpu/lib/python3.10/site-packages/django/utils/deprecation.py", line 120, in __call__
    response = response or self.get_response(request)
  File "/app/venv_awsgpu/lib/python3.10/site-packages/django/core/handlers/exception.py", line 57, in inner
    response = response_for_exception(request, exc)
  File "/app/venv_awsgpu/lib/python3.10/site-packages/django/core/handlers/exception.py", line 141, in response_for_exception
    response = handle_uncaught_exception(
  File "/app/venv_awsgpu/lib/python3.10/site-packages/django/core/handlers/exception.py", line 182, in handle_uncaught_exception
    return debug.technical_500_response(request, *exc_info)
  File "/app/venv_awsgpu/lib/python3.10/site-packages/django/views/debug.py", line 69, in technical_500_response
    html = reporter.get_traceback_html()
  File "/app/venv_awsgpu/lib/python3.10/site-packages/django/views/debug.py", line 428, in get_traceback_html
    c = Context(self.get_traceback_data(), use_l10n=False)
  File "/app/venv_awsgpu/lib/python3.10/site-packages/django/views/debug.py", line 411, in get_traceback_data
    c["raising_view_name"] = get_caller(self.request)
  File "/app/venv_awsgpu/lib/python3.10/site-packages/django/views/debug.py", line 102, in get_caller
    resolver_match = resolve(request.path)
  File "/app/venv_awsgpu/lib/python3.10/site-packages/django/urls/base.py", line 25, in resolve
    return get_resolver(urlconf).resolve(path)
  File "/app/venv_awsgpu/lib/python3.10/site-packages/django/urls/resolvers.py", line 666, in resolve
    for pattern in self.url_patterns:
  File "/app/venv_awsgpu/lib/python3.10/site-packages/django/utils/functional.py", line 47, in __get__
    res = instance.__dict__[self.name] = self.func(instance)
  File "/app/venv_awsgpu/lib/python3.10/site-packages/django/urls/resolvers.py", line 718, in url_patterns
    patterns = getattr(self.urlconf_module, "urlpatterns", self.urlconf_module)
  File "/app/venv_awsgpu/lib/python3.10/site-packages/django/utils/functional.py", line 47, in __get__
    res = instance.__dict__[self.name] = self.func(instance)
  File "/app/venv_awsgpu/lib/python3.10/site-packages/django/urls/resolvers.py", line 711, in urlconf_module
    return import_module(self.urlconf_name)
  File "/usr/lib/python3.10/importlib/__init__.py", line 126, in import_module
    return _bootstrap._gcd_import(name[level:], package, level)
  File "<frozen importlib._bootstrap>", line 1050, in _gcd_import
  File "<frozen importlib._bootstrap>", line 1027, in _find_and_load
  File "<frozen importlib._bootstrap>", line 1006, in _find_and_load_unlocked
  File "<frozen importlib._bootstrap>", line 688, in _load_unlocked
  File "<frozen importlib._bootstrap_external>", line 883, in exec_module
  File "<frozen importlib._bootstrap>", line 241, in _call_with_frames_removed
  File "/app/aws_gpu_monitoring/aws_gpu_monitoring/urls.py", line 22, in <module>
    path('', include('server_manager.urls')),  # server_manager 앱의 URL 포함
  File "/app/venv_awsgpu/lib/python3.10/site-packages/django/urls/conf.py", line 39, in include
    urlconf_module = import_module(urlconf_module)
  File "/usr/lib/python3.10/importlib/__init__.py", line 126, in import_module
    return _bootstrap._gcd_import(name[level:], package, level)
  File "<frozen importlib._bootstrap>", line 1050, in _gcd_import
  File "<frozen importlib._bootstrap>", line 1027, in _find_and_load
  File "<frozen importlib._bootstrap>", line 1006, in _find_and_load_unlocked
  File "<frozen importlib._bootstrap>", line 688, in _load_unlocked
  File "<frozen importlib._bootstrap_external>", line 883, in exec_module
  File "<frozen importlib._bootstrap>", line 241, in _call_with_frames_removed
  File "/app/aws_gpu_monitoring/server_manager/urls.py", line 2, in <module>
    from . import views
  File "/app/aws_gpu_monitoring/server_manager/views.py", line 8, in <module>
    from .ec2_service import EC2Service
  File "/app/aws_gpu_monitoring/server_manager/ec2_service.py", line 7, in <module>
    from server_manager.models.instance import Instance
  File "/app/aws_gpu_monitoring/server_manager/models/__init__.py", line 1, in <module>
    from .instance import Instance
  File "/app/aws_gpu_monitoring/server_manager/models/instance.py", line 3, in <module>
    class Instance(models.Model):
  File "/app/venv_awsgpu/lib/python3.10/site-packages/django/db/models/base.py", line 136, in __new__
    raise RuntimeError(
RuntimeError: Model class server_manager.models.instance.Instance doesn't declare an explicit app_label and isn't in an application in INSTALLED_APPS.

During handling of the above exception, another exception occurred:

Traceback (most recent call last):
  File "/app/venv_awsgpu/lib/python3.10/site-packages/django/core/handlers/exception.py", line 55, in inner
    response = get_response(request)
  File "/app/venv_awsgpu/lib/python3.10/site-packages/django/utils/deprecation.py", line 120, in __call__
    response = response or self.get_response(request)
  File "/app/venv_awsgpu/lib/python3.10/site-packages/django/core/handlers/exception.py", line 57, in inner
    response = response_for_exception(request, exc)
  File "/app/venv_awsgpu/lib/python3.10/site-packages/django/core/handlers/exception.py", line 141, in response_for_exception
    response = handle_uncaught_exception(
  File "/app/venv_awsgpu/lib/python3.10/site-packages/django/core/handlers/exception.py", line 182, in handle_uncaught_exception
    return debug.technical_500_response(request, *exc_info)
  File "/app/venv_awsgpu/lib/python3.10/site-packages/django/views/debug.py", line 69, in technical_500_response
    html = reporter.get_traceback_html()
  File "/app/venv_awsgpu/lib/python3.10/site-packages/django/views/debug.py", line 428, in get_traceback_html
    c = Context(self.get_traceback_data(), use_l10n=False)
  File "/app/venv_awsgpu/lib/python3.10/site-packages/django/views/debug.py", line 411, in get_traceback_data
    c["raising_view_name"] = get_caller(self.request)
  File "/app/venv_awsgpu/lib/python3.10/site-packages/django/views/debug.py", line 102, in get_caller
    resolver_match = resolve(request.path)
  File "/app/venv_awsgpu/lib/python3.10/site-packages/django/urls/base.py", line 25, in resolve
    return get_resolver(urlconf).resolve(path)
  File "/app/venv_awsgpu/lib/python3.10/site-packages/django/urls/resolvers.py", line 666, in resolve
    for pattern in self.url_patterns:
  File "/app/venv_awsgpu/lib/python3.10/site-packages/django/utils/functional.py", line 47, in __get__
    res = instance.__dict__[self.name] = self.func(instance)
  File "/app/venv_awsgpu/lib/python3.10/site-packages/django/urls/resolvers.py", line 718, in url_patterns
    patterns = getattr(self.urlconf_module, "urlpatterns", self.urlconf_module)
  File "/app/venv_awsgpu/lib/python3.10/site-packages/django/utils/functional.py", line 47, in __get__
    res = instance.__dict__[self.name] = self.func(instance)
  File "/app/venv_awsgpu/lib/python3.10/site-packages/django/urls/resolvers.py", line 711, in urlconf_module
    return import_module(self.urlconf_name)
  File "/usr/lib/python3.10/importlib/__init__.py", line 126, in import_module
    return _bootstrap._gcd_import(name[level:], package, level)
  File "<frozen importlib._bootstrap>", line 1050, in _gcd_import
  File "<frozen importlib._bootstrap>", line 1027, in _find_and_load
  File "<frozen importlib._bootstrap>", line 1006, in _find_and_load_unlocked
  File "<frozen importlib._bootstrap>", line 688, in _load_unlocked
  File "<frozen importlib._bootstrap_external>", line 883, in exec_module
  File "<frozen importlib._bootstrap>", line 241, in _call_with_frames_removed
  File "/app/aws_gpu_monitoring/aws_gpu_monitoring/urls.py", line 22, in <module>
    path('', include('server_manager.urls')),  # server_manager 앱의 URL 포함
  File "/app/venv_awsgpu/lib/python3.10/site-packages/django/urls/conf.py", line 39, in include
    urlconf_module = import_module(urlconf_module)
  File "/usr/lib/python3.10/importlib/__init__.py", line 126, in import_module
    return _bootstrap._gcd_import(name[level:], package, level)
  File "<frozen importlib._bootstrap>", line 1050, in _gcd_import
  File "<frozen importlib._bootstrap>", line 1027, in _find_and_load
  File "<frozen importlib._bootstrap>", line 1006, in _find_and_load_unlocked
  File "<frozen importlib._bootstrap>", line 688, in _load_unlocked
  File "<frozen importlib._bootstrap_external>", line 883, in exec_module
  File "<frozen importlib._bootstrap>", line 241, in _call_with_frames_removed
  File "/app/aws_gpu_monitoring/server_manager/urls.py", line 2, in <module>
    from . import views
  File "/app/aws_gpu_monitoring/server_manager/views.py", line 8, in <module>
    from .ec2_service import EC2Service
  File "/app/aws_gpu_monitoring/server_manager/ec2_service.py", line 7, in <module>
    from server_manager.models.instance import Instance
  File "/app/aws_gpu_monitoring/server_manager/models/__init__.py", line 1, in <module>
    from .instance import Instance
  File "/app/aws_gpu_monitoring/server_manager/models/instance.py", line 3, in <module>
    class Instance(models.Model):
  File "/app/venv_awsgpu/lib/python3.10/site-packages/django/db/models/base.py", line 136, in __new__
    raise RuntimeError(
RuntimeError: Model class server_manager.models.instance.Instance doesn't declare an explicit app_label and isn't in an application in INSTALLED_APPS.

During handling of the above exception, another exception occurred:

Traceback (most recent call last):
  File "/app/venv_awsgpu/lib/python3.10/site-packages/django/core/handlers/exception.py", line 55, in inner
    response = get_response(request)
  File "/app/venv_awsgpu/lib/python3.10/site-packages/django/utils/deprecation.py", line 120, in __call__
    response = response or self.get_response(request)
  File "/app/venv_awsgpu/lib/python3.10/site-packages/django/core/handlers/exception.py", line 57, in inner
    response = response_for_exception(request, exc)
  File "/app/venv_awsgpu/lib/python3.10/site-packages/django/core/handlers/exception.py", line 141, in response_for_exception
    response = handle_uncaught_exception(
  File "/app/venv_awsgpu/lib/python3.10/site-packages/django/core/handlers/exception.py", line 182, in handle_uncaught_exception
    return debug.technical_500_response(request, *exc_info)
  File "/app/venv_awsgpu/lib/python3.10/site-packages/django/views/debug.py", line 69, in technical_500_response
    html = reporter.get_traceback_html()
  File "/app/venv_awsgpu/lib/python3.10/site-packages/django/views/debug.py", line 428, in get_traceback_html
    c = Context(self.get_traceback_data(), use_l10n=False)
  File "/app/venv_awsgpu/lib/python3.10/site-packages/django/views/debug.py", line 411, in get_traceback_data
    c["raising_view_name"] = get_caller(self.request)
  File "/app/venv_awsgpu/lib/python3.10/site-packages/django/views/debug.py", line 102, in get_caller
    resolver_match = resolve(request.path)
  File "/app/venv_awsgpu/lib/python3.10/site-packages/django/urls/base.py", line 25, in resolve
    return get_resolver(urlconf).resolve(path)
  File "/app/venv_awsgpu/lib/python3.10/site-packages/django/urls/resolvers.py", line 666, in resolve
    for pattern in self.url_patterns:
  File "/app/venv_awsgpu/lib/python3.10/site-packages/django/utils/functional.py", line 47, in __get__
    res = instance.__dict__[self.name] = self.func(instance)
  File "/app/venv_awsgpu/lib/python3.10/site-packages/django/urls/resolvers.py", line 718, in url_patterns
    patterns = getattr(self.urlconf_module, "urlpatterns", self.urlconf_module)
  File "/app/venv_awsgpu/lib/python3.10/site-packages/django/utils/functional.py", line 47, in __get__
    res = instance.__dict__[self.name] = self.func(instance)
  File "/app/venv_awsgpu/lib/python3.10/site-packages/django/urls/resolvers.py", line 711, in urlconf_module
    return import_module(self.urlconf_name)
  File "/usr/lib/python3.10/importlib/__init__.py", line 126, in import_module
    return _bootstrap._gcd_import(name[level:], package, level)
  File "<frozen importlib._bootstrap>", line 1050, in _gcd_import
  File "<frozen importlib._bootstrap>", line 1027, in _find_and_load
  File "<frozen importlib._bootstrap>", line 1006, in _find_and_load_unlocked
  File "<frozen importlib._bootstrap>", line 688, in _load_unlocked
  File "<frozen importlib._bootstrap_external>", line 883, in exec_module
  File "<frozen importlib._bootstrap>", line 241, in _call_with_frames_removed
  File "/app/aws_gpu_monitoring/aws_gpu_monitoring/urls.py", line 22, in <module>
    path('', include('server_manager.urls')),  # server_manager 앱의 URL 포함
  File "/app/venv_awsgpu/lib/python3.10/site-packages/django/urls/conf.py", line 39, in include
    urlconf_module = import_module(urlconf_module)
  File "/usr/lib/python3.10/importlib/__init__.py", line 126, in import_module
    return _bootstrap._gcd_import(name[level:], package, level)
  File "<frozen importlib._bootstrap>", line 1050, in _gcd_import
  File "<frozen importlib._bootstrap>", line 1027, in _find_and_load
  File "<frozen importlib._bootstrap>", line 1006, in _find_and_load_unlocked
  File "<frozen importlib._bootstrap>", line 688, in _load_unlocked
  File "<frozen importlib._bootstrap_external>", line 883, in exec_module
  File "<frozen importlib._bootstrap>", line 241, in _call_with_frames_removed
  File "/app/aws_gpu_monitoring/server_manager/urls.py", line 2, in <module>
    from . import views
  File "/app/aws_gpu_monitoring/server_manager/views.py", line 8, in <module>
    from .ec2_service import EC2Service
  File "/app/aws_gpu_monitoring/server_manager/ec2_service.py", line 7, in <module>
    from server_manager.models.instance import Instance
  File "/app/aws_gpu_monitoring/server_manager/models/__init__.py", line 1, in <module>
    from .instance import Instance
  File "/app/aws_gpu_monitoring/server_manager/models/instance.py", line 3, in <module>
    class Instance(models.Model):
  File "/app/venv_awsgpu/lib/python3.10/site-packages/django/db/models/base.py", line 136, in __new__
    raise RuntimeError(
RuntimeError: Model class server_manager.models.instance.Instance doesn't declare an explicit app_label and isn't in an application in INSTALLED_APPS.

During handling of the above exception, another exception occurred:

Traceback (most recent call last):
  File "/app/venv_awsgpu/lib/python3.10/site-packages/gunicorn/workers/sync.py", line 134, in handle
    self.handle_request(listener, req, client, addr)
  File "/app/venv_awsgpu/lib/python3.10/site-packages/gunicorn/workers/sync.py", line 177, in handle_request
    respiter = self.wsgi(environ, resp.start_response)
  File "/app/venv_awsgpu/lib/python3.10/site-packages/django/core/handlers/wsgi.py", line 124, in __call__
    response = self.get_response(request)
  File "/app/venv_awsgpu/lib/python3.10/site-packages/django/core/handlers/base.py", line 140, in get_response
    response = self._middleware_chain(request)
  File "/app/venv_awsgpu/lib/python3.10/site-packages/django/core/handlers/exception.py", line 57, in inner
    response = response_for_exception(request, exc)
  File "/app/venv_awsgpu/lib/python3.10/site-packages/django/core/handlers/exception.py", line 141, in response_for_exception
    response = handle_uncaught_exception(
  File "/app/venv_awsgpu/lib/python3.10/site-packages/django/core/handlers/exception.py", line 182, in handle_uncaught_exception
    return debug.technical_500_response(request, *exc_info)
  File "/app/venv_awsgpu/lib/python3.10/site-packages/django/views/debug.py", line 69, in technical_500_response
    html = reporter.get_traceback_html()
  File "/app/venv_awsgpu/lib/python3.10/site-packages/django/views/debug.py", line 428, in get_traceback_html
    c = Context(self.get_traceback_data(), use_l10n=False)
  File "/app/venv_awsgpu/lib/python3.10/site-packages/django/views/debug.py", line 411, in get_traceback_data
    c["raising_view_name"] = get_caller(self.request)
  File "/app/venv_awsgpu/lib/python3.10/site-packages/django/views/debug.py", line 102, in get_caller
    resolver_match = resolve(request.path)
  File "/app/venv_awsgpu/lib/python3.10/site-packages/django/urls/base.py", line 25, in resolve
    return get_resolver(urlconf).resolve(path)
  File "/app/venv_awsgpu/lib/python3.10/site-packages/django/urls/resolvers.py", line 666, in resolve
    for pattern in self.url_patterns:
  File "/app/venv_awsgpu/lib/python3.10/site-packages/django/utils/functional.py", line 47, in __get__
    res = instance.__dict__[self.name] = self.func(instance)
  File "/app/venv_awsgpu/lib/python3.10/site-packages/django/urls/resolvers.py", line 718, in url_patterns
    patterns = getattr(self.urlconf_module, "urlpatterns", self.urlconf_module)
  File "/app/venv_awsgpu/lib/python3.10/site-packages/django/utils/functional.py", line 47, in __get__
    res = instance.__dict__[self.name] = self.func(instance)
  File "/app/venv_awsgpu/lib/python3.10/site-packages/django/urls/resolvers.py", line 711, in urlconf_module
    return import_module(self.urlconf_name)
  File "/usr/lib/python3.10/importlib/__init__.py", line 126, in import_module
    return _bootstrap._gcd_import(name[level:], package, level)
  File "<frozen importlib._bootstrap>", line 1050, in _gcd_import
  File "<frozen importlib._bootstrap>", line 1027, in _find_and_load
  File "<frozen importlib._bootstrap>", line 1006, in _find_and_load_unlocked
  File "<frozen importlib._bootstrap>", line 688, in _load_unlocked
  File "<frozen importlib._bootstrap_external>", line 883, in exec_module
  File "<frozen importlib._bootstrap>", line 241, in _call_with_frames_removed
  File "/app/aws_gpu_monitoring/aws_gpu_monitoring/urls.py", line 22, in <module>
    path('', include('server_manager.urls')),  # server_manager 앱의 URL 포함
  File "/app/venv_awsgpu/lib/python3.10/site-packages/django/urls/conf.py", line 39, in include
    urlconf_module = import_module(urlconf_module)
  File "/usr/lib/python3.10/importlib/__init__.py", line 126, in import_module
    return _bootstrap._gcd_import(name[level:], package, level)
  File "<frozen importlib._bootstrap>", line 1050, in _gcd_import
  File "<frozen importlib._bootstrap>", line 1027, in _find_and_load
  File "<frozen importlib._bootstrap>", line 1006, in _find_and_load_unlocked
  File "<frozen importlib._bootstrap>", line 688, in _load_unlocked
  File "<frozen importlib._bootstrap_external>", line 883, in exec_module
  File "<frozen importlib._bootstrap>", line 241, in _call_with_frames_removed
  File "/app/aws_gpu_monitoring/server_manager/urls.py", line 2, in <module>
    from . import views
  File "/app/aws_gpu_monitoring/server_manager/views.py", line 8, in <module>
    from .ec2_service import EC2Service
  File "/app/aws_gpu_monitoring/server_manager/ec2_service.py", line 7, in <module>
    from server_manager.models.instance import Instance
  File "/app/aws_gpu_monitoring/server_manager/models/__init__.py", line 1, in <module>
    from .instance import Instance
  File "/app/aws_gpu_monitoring/server_manager/models/instance.py", line 3, in <module>
    class Instance(models.Model):
  File "/app/venv_awsgpu/lib/python3.10/site-packages/django/db/models/base.py", line 136, in __new__
    raise RuntimeError(
RuntimeError: Model class server_manager.models.instance.Instance doesn't declare an explicit app_label and isn't in an application in INSTALLED_APPS.
[2025-07-01 04:05:34 +0000] [137] [INFO] Worker exiting (pid: 137)
[2025-07-01 04:05:34 +0000] [131] [INFO] Handling signal: term
[2025-07-01 04:05:34 +0000] [139] [INFO] Worker exiting (pid: 139)
[2025-07-01 04:05:34 +0000] [138] [INFO] Worker exiting (pid: 138)
[2025-07-01 04:05:34 +0000] [131] [INFO] Shutting down: Master
[2025-07-01 04:05:34 +0000] [146] [INFO] Starting gunicorn 23.0.0
[2025-07-01 04:05:34 +0000] [146] [INFO] Listening at: unix:/app/aws_gpu_monitoring/gunicorn.sock (146)
[2025-07-01 04:05:34 +0000] [146] [INFO] Using worker: sync
[2025-07-01 04:05:34 +0000] [152] [INFO] Booting worker with pid: 152
[2025-07-01 04:05:34 +0000] [153] [INFO] Booting worker with pid: 153
[2025-07-01 04:05:34 +0000] [154] [INFO] Booting worker with pid: 154
[2025-07-01 04:15:04 +0000] [154] [INFO] Worker exiting (pid: 154)
[2025-07-01 04:15:04 +0000] [152] [INFO] Worker exiting (pid: 152)
[2025-07-01 04:15:04 +0000] [146] [INFO] Handling signal: term
[2025-07-01 04:15:04 +0000] [146] [ERROR] Worker (pid:152) was sent SIGTERM!
[2025-07-01 04:15:04 +0000] [153] [INFO] Worker exiting (pid: 153)
[2025-07-01 04:15:04 +0000] [146] [ERROR] Worker (pid:154) was sent SIGTERM!
[2025-07-01 04:15:04 +0000] [146] [INFO] Shutting down: Master
[2025-07-01 04:15:05 +0000] [161] [INFO] Starting gunicorn 23.0.0
[2025-07-01 04:15:05 +0000] [161] [INFO] Listening at: unix:/app/aws_gpu_monitoring/gunicorn.sock (161)
[2025-07-01 04:15:05 +0000] [161] [INFO] Using worker: sync
[2025-07-01 04:15:05 +0000] [167] [INFO] Booting worker with pid: 167
[2025-07-01 04:15:05 +0000] [168] [INFO] Booting worker with pid: 168
[2025-07-01 04:15:05 +0000] [169] [INFO] Booting worker with pid: 169
